Workbook

Sheet ListOfValues
B1: Aktif | C1: Tahunan | D1: Audited | E1: WTP | F1: tahun pertama
B2: Tidak Aktif | C2: Tengah Tahunan | D2: Un Audited | E2: WTP-PP | F2: tahun pertama (setelah cooling-off period)
C3: Triwulanan | D3: Limited Review | E3: WDP | F3: tahun ke-2 berturut-turut
E4: DISCLAIMER | F4: tahun ke-3 berturut-turut
E5: ADVERSE | F5: lebih dari 3 tahun berturut-turut

Sheet Informasi
A1: Petunjuk pengisian template Laporan Keuangan Manajer Investasi
A3: 1 | B3: Isi data umum perusahaan, data audit dan informasi tambahan atas Laporan Keuangan pada sheet Data Umum
A4: 2 | B4: Isi informasi terkait aset, kewajiban, dan modal kerja perusahaan pada sheet Laporan Posisi Keuangan (LPKMI)
A5: 3 | B5: Jika perusahaan memiliki akun tertentu yang tidak terdapat pada pilihan di Laporan Posisi Keuangan, silahkan memasukkan informasi tersebut pada akun Lain-lain.
A6: 4 | B6: Isi informasi terkait pendapatan dan beban pada sheet Laporan Laba Rugi (LLRKMI)
A7: 5 | B7: Akun-akun pada BEBAN yang menjadi komponen dari "Total Beban" pada LLRKMI diisi dengan angka positif (tidak menambahkan tanda "-")
A8: 6 | B8: Jika perusahaan memiliki akun tertentu yang tidak terdapat pada pilihan di Laporan Laba Rugi, silahkan memasukkan informasi tersebut pada akun Lain-lain.
A9: 7 | B9: Isi informasi terkait perubahan ekuitas pada sheet Laporan Perubahan Ekuitas
A10: 8 | B10: Isi informasi terkait perubahan ekuitas pada sheet Laporan Arus Kas
A11: 9 | B11: Cek status validasi laporan pada sheet Validasi
A12: 10 | B12: Laporan yang dikirimkan ke Otoritas Jasa Keuangan adalah laporan dengan Status Validasi Keseluruhan = OK
A13: 11 | B13: Pengiriman Laporan Keuangan Elektronik disertai dengan pengiriman hardcopy dan/atau mailingroom OJK

Sheet Validasi
E7: Status Validasi Laporan Secara Keseluruhan: | G7: =IF(AND(G10="OK",G11="OK",G12="OK",G13="OK",G14="OK",G15="OK",G16="OK",G17="OK",G18="OK",G19="OK"),"OK","NOT OK") -> OK
C9: No | D9: Sheet | E9: Keterangan | F9: Formula | G9: Status
C10: 1 | D10: LPKMI | E10: Pada Laporan Posisi Keuangan, Jumlah Aset tahun berjalan harus sama dengan Jumlah Liabilitas + Jumlah Ekuitas | F10: LPKMIG44=LPKMI!G84 | G10: =IF(OR(('Laporan Posisi Keuangan'!G44-'Laporan Posisi Keuangan'!G84)>=3,('Laporan Posisi Keuangan'!G44-'Laporan Posisi Keuangan'!G84)<=-3),"NOT OK","OK") -> OK
C11: 2 | D11: LPKMI | E11: Pada Laporan Posisi Keuangan, Jumlah Aset tahun sebelumnya harus sama dengan Jumlah Liabilitas + Jumlah Ekuitas | F11: LPKMIH44=LPKMI!H84 | G11: =IF(OR(('Laporan Posisi Keuangan'!H44-'Laporan Posisi Keuangan'!H84)>=3,('Laporan Posisi Keuangan'!H44-'Laporan Posisi Keuangan'!H84)<=-3),"NOT OK","OK") -> OK
C12: 3 | D12: LAKMI-LPKMI | E12: Kas dan Setara Kas Akhir Periode Berjalan harus sama dengan Kas dan Setara Kas pada Laporan Posisi Keuangan Periode berjalan | F12: LAKMI!E49=lpkmi!G17+lpkmi!G18 | G12: =IF(OR(('Laporan Arus Kas'!E49-'Laporan Posisi Keuangan'!G17-'Laporan Posisi Keuangan'!G18)>=3,('Laporan Arus Kas'!E49-'Laporan Posisi Keuangan'!G17-'Laporan Posisi Keuangan'!G18)<=-3),"NOT OK","OK") -> OK
C13: 4 | D13: LAKMI-LPKMI | E13: Kas dan Setara Kas Akhir Periode Sebelumnya harus sama dengan Kas dan Setara Kas pada Laporan Posisi Keuangan Periode Sebelumnya | F13: LAKMI!F49=lpkmi!H17+lpkmi!H18 | G13: =IF(OR(('Laporan Arus Kas'!F49-'Laporan Posisi Keuangan'!H17-'Laporan Posisi Keuangan'!H18)>=3,('Laporan Arus Kas'!F49-'Laporan Posisi Keuangan'!H17-'Laporan Posisi Keuangan'!H18)<=-3),"NOT OK","OK") -> OK
C14: 5 | D14: LLRKMI | E14: Pada Laporan Laba Rugi, Laba Rugi Periode Berjalan harus sama dengan Total Laba Rugi yang dapat Diatribusikan | F14: LLRKMI!E68=LLRKMI!E78 | G14: =IF(OR(('Laporan Laba Rugi'!E68-'Laporan Laba Rugi'!E78)>=3,('Laporan Laba Rugi'!E68-'Laporan Laba Rugi'!E78)<=-3),"NOT OK","OK") -> OK
C15: 6 | D15: LLRKMI | E15: Pada Laporan Laba Rugi, Laba Rugi Periode Sebelumnya harus sama dengan Total Laba Rugi yang dapat Diatribusikan Periode Sebelumnya | F15: LLRKMI!F68=LLRKMI!F78 | G15: =IF(OR(('Laporan Laba Rugi'!F68-'Laporan Laba Rugi'!F78)>=3,('Laporan Laba Rugi'!F68-'Laporan Laba Rugi'!F78)<=-3),"NOT OK","OK") -> OK
C16: 7 | D16: LLRKMI | E16: Pada Laporan Laba Rugi, Penghasilan Komprehensif harus sama dengan Total Penghasilan Komprehensif yang dapat Diatribusikan | F16: LLRKMI!E74=LLRKMI!E82 | G16: =IF(OR(('Laporan Laba Rugi'!E74-'Laporan Laba Rugi'!E82)>=3,('Laporan Laba Rugi'!E74-'Laporan Laba Rugi'!E82)<=-3),"NOT OK","OK") -> OK
C17: 8 | D17: LLRKMI | E17: Pada Laporan Laba Rugi, Penghasilan Komprehensif periode sebelumnya harus sama dengan Total Penghasilan Komprehensif yang dapat Diatribusikan | F17: LLRKMI!F74=LLRKMI!F82 | G17: =IF(OR(('Laporan Laba Rugi'!F74-'Laporan Laba Rugi'!F82)>=3,('Laporan Laba Rugi'!F74-'Laporan Laba Rugi'!F82)<=-3),"NOT OK","OK") -> OK
C18: 9 | D18: LPEMI-LPKMI | E18: Jumlah Ekuitas pada Laporan Posisi Keuangan harus sama dengan Jumlah Ekuitas pada Laporan Perubahan Ekuitas | F18: LPKMI!G83=LPEMI!P28 | G18: =IF(OR(('Laporan Posisi Keuangan'!G83-'Laporan Perubahan Ekuitas'!P28)>=3,('Laporan Posisi Keuangan'!G83-'Laporan Perubahan Ekuitas'!P28)<=-3),"NOT OK","OK") -> OK
C19: 10 | D19: LPEMI-LPKMI | E19: Jumlah Ekuitas pada Laporan Posisi Keuangan Peridode Sebelumnya harus sama dengan Jumlah Ekuitas pada Laporan Perubahan Ekuitas | F19: LPKMI!H83=LPEMI!P23 | G19: =IF(OR(('Laporan Posisi Keuangan'!H83-'Laporan Perubahan Ekuitas'!P23)>=3,('Laporan Posisi Keuangan'!H83-'Laporan Perubahan Ekuitas'!P23)<=-3),"NOT OK","OK") -> OK

Sheet Data Umum
B2: T
B3: LKTPA | C3: Data Umum | G3: =MONTH(D9) -> 12 | H3: 1 | I3: Januari
G4: =VLOOKUP(G3,$H$3:$I$12,2,FALSE) -> Desember | H4: 2 | I4: Februari
B5: LKT01DTU0001 | C5: Tanggal Pelaporan | D5: 46098 | H5: 3 | I5: Maret
B6: LKT01DTU0002 | C6: Kode Perusahaan / Pihak | D6: CC002 | H6: 4 | I6: April
B7: LKT01DTU0003 | C7: Nama Perusahaan / Pihak | D7: PT MANDIRI MANAJEMEN INVESTASI | H7: 5 | I7: Mei
B8: LKT01DTU0004 | C8: Alamat Perusahaan / Pihak | D8: MENARA MANDIRI 2 LT. 15, JL. JEND SUDIRMAN KAV 54-55, JAKARTA | H8: 6 | I8: Juni
B9: LKT01DTU0005 | C9: Periode Pelaporan | D9: 46022 | H9: 9 | I9: September
B10: LKT01DTU0006 | C10: Bulan Pelaporan | D10: =IF(ISERR(G4), "", G4) -> Desember | H10: 10 | I10: Oktober
B11: LKT01DTU0007 | C11: Tahun Fiskal | D11: =IF(ISBLANK(D9),"",IFERROR(YEAR(D9), "")) -> 2025 | H11: 11 | I11: November
B12: LKT01DTU0008 | C12: Jenis Periode Pelaporan | D12: Tahunan | H12: 12 | I12: Desember
B13: LKT01DTU0009 | C13: Nama Direksi / Penanggung Jawab | D13: HARDIYANTO PILIA
B14: LKT01DTU0010 | C14: Jabatan Direksi / Penanggung Jawab | D14: DIREKTUR
C16: Data Audit
B17: LKT01DTU0011 | C17: Nama Kantor Akuntan Publik (KAP) | D17: KANTOR AKUNTAN PUBLIK PURWANTO SUSANTI DAN SURJA
B18: LKT01DTU0016 | C18: SK Izin Kantor Akuntan Publik | D18: 69/MK/SK/2025
B19: LKT01DTU0017 | C19: Status Kantor Akuntan Publik | D19: Aktif
B20: LKT01DTU0013 | C20: Nama Akuntan Publik (AP) | D20: CHRISTOPHORUS ALVIN KOSSIM
B21: LKT01DTU0018 | C21: Nomor Registrasi Akuntan Publik | D21: AP.1681
B22: LKT01DTU0012 | C22: Nomor STTD PM Akuntan Publik | D22: STTD.KAP-17/PM.021/2025
B23: LKT01DTU0019 | C23: Status Akuntan Publik | D23: Aktif
B24: LKT01DTU0020 | C24: Periode Penugasan AP | D24: tahun pertama (setelah cooling-off period)
B25: LKT01DTU0021 | C25: Periode Audit Awal | D25: 45658
B26: LKT01DTU0022 | C26: Periode Audit Akhir | D26: 46022
B27: LKT01DTU0023 | C27: Jenis Audit | D27: Audited
B28: LKT01DTU0014 | C28: Opini Laporan | D28: WTP

Sheet Laporan Posisi Keuangan
B2: LPKA
B3: 1
D7: =UPPER('Data Umum'!D7) -> PT MANDIRI MANAJEMEN INVESTASI
D9: Laporan Posisi Keuangan
D11: ="Per 31 Desember "&CONCATENATE(TEXT('Data Umum'!D9, "YYYY")) -> Per 31 Desember 2025
D14: Akun | G14: =CONCATENATE(TEXT('Data Umum'!D9, "YYYY")) -> 2025 | H14: =CONCATENATE(TEXT(DATE(YEAR('Data Umum'!D9), MONTH('Data Umum'!D9)-12, DAY('Data Umum'!D9)), "YYYY")) -> 2024
A15: KODE LAMA | B15: MAP CODE | C15: KODE LAMA | F15: Catatan Mapping
A16: LKT01LPK0023 | B16: A | C16: LKT01LPK0001 | D16: ASET | G16: =IFERROR(G17, 0)+IFERROR(G18, 0)+IFERROR(G19, 0)+IFERROR(G20, 0)+IFERROR(G21, 0)+IFERROR(G22, 0)+IFERROR(G25, 0)+IFERROR(G28, 0)+IFERROR(G31, 0)+IFERROR(G34, 0)+IFERROR(G35, 0)+IFERROR(G36, 0)+IFERROR(G37, 0)+IFERROR(G38, 0)+IFERROR(G39, 0)+IFERROR(G40, 0)+IFERROR(G41, 0)+IFERROR(G42, 0)+IFERROR(G43, 0) -> 413872455749 | H16: =IFERROR(H17, 0)+IFERROR(H18, 0)+IFERROR(H19, 0)+IFERROR(H20, 0)+IFERROR(H21, 0)+IFERROR(H22, 0)+IFERROR(H25, 0)+IFERROR(H28, 0)+IFERROR(H31, 0)+IFERROR(H34, 0)+IFERROR(H35, 0)+IFERROR(H36, 0)+IFERROR(H37, 0)+IFERROR(H38, 0)+IFERROR(H39, 0)+IFERROR(H40, 0)+IFERROR(H41, 0)+IFERROR(H42, 0)+IFERROR(H43, 0) -> 448051314959
A17: LKT01LPK0002 | B17: A.1 | C17: LKT01LPK0002 | D17: Kas dan Setara Kas | G17: 212255442891 | H17: 96483958730
A18: #N/A | B18: A.2 | C18: LKT01LPK0060 | D18: Kas dan Setara Kas yang Dibatasi Penggunaannya | F18: Akun Baru | G18: 0 | H18: 0
A19: LKT01LPK0003 | B19: A.3 | C19: LKT01LPK0003 | D19: Deposito Berjangka | G19: 0 | H19: 0
A20: LKT01LPK0005 | B20: A.4 | C20: LKT01LPK0005 | D20: Portofolio Efek | G20: 69233684184 | H20: 234412261112
A21: #N/A | B21: A.5 | C21: LKT01LPK0006 | D21: Portofolio Efek yang Dialihkan | G21: 0 | H21: 0
A22: #N/A | B22: A.6 | C22: LKT01LPK0061 | D22: Piutang Usaha | G22: =G23+G24 -> 0 | H22: =H23+H24 -> 0
A23: #N/A | B23: A.6.1 | C23: LKT01LPK0062 | D23: Pihak Ketiga | G23: 0 | H23: 0
A24: #N/A | B24: A.6.2 | C24: LKT01LPK0063 | D24: Pihak Berelasi | G24: 0 | H24: 0
A25: #N/A | B25: A.7 | C25: LKT01LPK0064 | D25: Piutang Transaksi sebagai Perantara Pedagang Efek (Kegiatan sebagai PPE) | G25: =G26+G27 -> 0 | H25: =H26+H27 -> 0
A26: #N/A | B26: A.7.1 | C26: LKT01LPK0065 | D26: Pihak Ketiga | G26: 0 | H26: 0
A27: #N/A | B27: A.7.2 | C27: LKT01LPK0066 | D27: Pihak Berelasi | G27: 0 | H27: 0
A28: LKT01LPK0012 | B28: A.8 | C28: LKT01LPK0012 | D28: Piutang Transaksi sebagai Penjaminan Emisi Efek (Kegiatan sebagai PEE) | G28: =G29+G30 -> 0 | H28: =H29+H30 -> 0
A29: #N/A | B29: A.8.1 | C29: LKT01LPK0067 | D29: Pihak Ketiga | G29: 0 | H29: 0
A30: #N/A | B30: A.8.2 | C30: LKT01LPK0068 | D30: Pihak Berelasi | G30: 0 | H30: 0
A31: LKT01LPK0013 | B31: A.9 | C31: LKT01LPK0013 | D31: Piutang Transaksi Pengelolaan Investasi (Kegiatan sebagai MI) | G31: =G32+G33 -> 36788210762 | H31: =H32+H33 -> 27381269283
A32: #N/A | B32: A.9.1 | C32: LKT01LPK0069 | D32: Pihak Ketiga | G32: 34782514333 | H32: 25475921939
A33: #N/A | B33: A.9.2 | C33: LKT01LPK0070 | D33: Pihak Berelasi | G33: 2005696429 | H33: 1905347344
A34: LKT01LPK0004 | B34: A.10 | C34: LKT01LPK0004 | D34: Piutang Transaksi Repo | G34: 0 | H34: 0
A35: LKT01LPK0014 | B35: A.11 | C35: LKT01LPK0014 | D35: Piutang Lain-Lain | G35: 405642191 | H35: 365854510
A36: LKT01LPK0015 | B36: A.12 | C36: LKT01LPK0015 | D36: Biaya Dibayar Dimuka | G36: 5456737153 | H36: 5235524226
A37: LKT01LPK0016 | B37: A.13 | C37: LKT01LPK0016 | D37: Pajak Dibayar Dimuka | G37: 0 | H37: 5689796732
A38: #N/A | B38: A.14 | C38: LKT01LPK0071 | D38: Investasi pada Entitas Asosiasi | G38: 62534173930 | H38: 62534173930
A39: #N/A | B39: A.15 | C39: LKT01LPK0017 | D39: Aset Tak Berwujud | G39: 0 | H39: 0
A40: LKT01LPK0021 | B40: A.16 | C40: LKT01LPK0021 | D40: Aset Hak Guna | G40: 9358840682 | H40: 233195876
A41: LKT01LPK0018 | B41: A.17 | C41: LKT01LPK0018 | D41: Aset Tetap | G41: 4912044363 | H41: 5382522454
A42: LKT01LPK0019 | B42: A.18 | C42: LKT01LPK0019 | D42: Aset Pajak Tangguhan | G42: 10567017412 | H42: 7857666372
A43: LKT01LPK0022 | B43: A.19 | C43: LKT01LPK0022 | D43: Aset Lain-Lain | G43: 2360662181 | H43: 2475091734
A44: LKT01LPK0023 | B44: A | C44: LKT01LPK0023 | D44: TOTAL ASET | G44: =G16 -> 413872455749 | H44: =H16 -> 448051314959
A45: LKT01LPK0044 | B45: B | C45: LKT01LPK0024 | D45: LIABILITAS | G45: =IFERROR(G46, 0)+IFERROR(G49, 0)+IFERROR(G52, 0)+IFERROR(G55, 0)+IFERROR(G58, 0)+IFERROR(G59, 0)+IFERROR(G60, 0)+IFERROR(G61, 0)+IFERROR(G62, 0)+IFERROR(G63, 0)+IFERROR(G64, 0)+IFERROR(G65, 0)+IFERROR(G66, 0)+IFERROR(G67, 0)+IFERROR(G68, 0)+IFERROR(G69, 0) -> 93751825643 | H45: =IFERROR(H46, 0)+IFERROR(H49, 0)+IFERROR(H52, 0)+IFERROR(H55, 0)+IFERROR(H58, 0)+IFERROR(H59, 0)+IFERROR(H60, 0)+IFERROR(H61, 0)+IFERROR(H62, 0)+IFERROR(H63, 0)+IFERROR(H64, 0)+IFERROR(H65, 0)+IFERROR(H66, 0)+IFERROR(H67, 0)+IFERROR(H68, 0)+IFERROR(H69, 0) -> 64447297741
A46: #N/A | B46: B.1 | C46: LKT01LPK0072 | D46: Utang Usaha | G46: =G47+G48 -> 0 | H46: =H47+H48 -> 0
A47: #N/A | B47: B.1.1 | C47: LKT01LPK0073 | D47: Pihak Ketiga | G47: 0 | H47: 0
A48: #N/A | B48: B.1.2 | C48: LKT01LPK0074 | D48: Pihak Berelasi | G48: 0 | H48: 0
...

Sheet Laporan Laba Rugi
B2: LLRKTLEA
B3: 1
C7: =UPPER('Data Umum'!D7) -> PT MANDIRI MANAJEMEN INVESTASI
C9: Laporan Laba Rugi Komprehensif
C10: -
C11: ="Untuk Tahun yang Berakhir Pada 31 Desember "&CONCATENATE(TEXT('Data Umum'!D9, "YYYY")) -> Untuk Tahun yang Berakhir Pada 31 Desember 2025
E14: ="Jumlah (Dalam Rupiah)" -> Jumlah (Dalam Rupiah)
A15: KODE LAMA | B15: MAP CODE | C15: Akun | E15: =CONCATENATE(TEXT('Data Umum'!D9, "YYYY")) -> 2025 | F15: =CONCATENATE(TEXT(DATE(YEAR('Data Umum'!D9), MONTH('Data Umum'!D9)-12, DAY('Data Umum'!D9)), "YYYY")) -> 2024
A16: LKT01LLR0001 | B16: A | C16: PENDAPATAN | E16: =E17+E31 -> 308970678934 | F16: =F17+F31 -> 308233286872
A17: LKT01LLR0066 | B17: A.1 | C17: Pendapatan dari kontrak dengan pelanggan | E17: =E18+E22+E30 -> 287496011368 | F17: =F18+F22+F30 -> 294948762371
A18: LKT01LLR0067 | B18: A.1.1 | C18: Pendapatan komisi | E18: =SUM(E19:E21) -> 0 | F18: =SUM(F19:F21) -> 0
A19: LKT01LLR0003 | B19: A.1.1.1 | C19: Perantara (fee broker) | E19: 0 | F19: 0
A20: LKT01LLR0068 | B20: A.1.1.2 | C20: Anggota sindikasi | E20: 0 | F20: 0
A21: LKT01LLR0006 | B21: A.1.1.3 | C21: Pendapatan Komisi Lainnya | E21: 0 | F21: 0
A22: LKT01LLR0069 | B22: A.1.2 | C22: Pendapatan jasa | E22: =SUM(E23,E27,E28,E29) -> 287496011368 | F22: =SUM(F23,F27,F28,F29) -> 294948762371
A23: LKT01LLR0015 | B23: A.1.2.1 | C23: Jasa Kegiatan Manajer Investasi: | E23: =SUM(E24:E26) -> 287496011368 | F23: =SUM(F24:F26) -> 294948762371
A24: LKT01LLR0016 | B24: A.1.2.1.1 | C24: - management fee | E24: 286630301484 | F24: 294861640566
A25: LKT01LLR0017 | B25: A.1.2.1.2 | C25: - subscription fee | E25: 803663448 | F25: 1608236
A26: LKT01LLR0018 | B26: A.1.2.1.3 | C26: - redemption fee | E26: 62046436 | F26: 85513569
A27: LKT01LLR0020 | B27: A.1.2.2 | C27: Jasa Kegiatan Penasihat Investasi | E27: 0 | F27: 0
A28: LKT01LLR0010 | B28: A.1.2.3 | C28: Jasa Penjamin emisi (lead underwriter) | E28: 0 | F28: 0
A29: LKT01LLR0011 | B29: A.1.2.4 | C29: Pendapatan Jasa Lainnya | E29: 0 | F29: 0
A30: LKT01LLR0070 | B30: A.1.3 | C30: Pendapatan dari kontrak dengan pelanggan lainnya | E30: 0 | F30: 0
A31: LKT01LLR0071 | B31: A.1.4 | C31: Pendapatan dari hasil investasi | E31: =E32+E37 -> 21474667566 | F31: =F32+F37 -> 13284524501
A32: LKT01LLR0072 | B32: A.1.4.1 | C32: Imbalan yang diterima dari hasil investasi | E32: =SUM(E33:E36) -> 11705659523 | F32: =SUM(F33:F36) -> 15153283719
A33: LKT01LLR0007 | B33: A.1.4.1.1 | C33: Pendapatan bunga | E33: 11705659523 | F33: 15153283719
A34: LKT01LLR0073 | B34: A.1.4.1.2 | C34: Imbal hasil dari Efek bersifat utang dan instrumen pasar uang | E34: 0 | F34: 0
A35: LKT01LLR0074 | B35: A.1.4.1.3 | C35: dividen dari Efek bersifat ekuitas. | E35: 0 | F35: 0
A36: LKT01LLR0075 | B36: A.1.4.1.4 | C36: Imbalan yang diterima dari hasil investasi lainnya | E36: 0 | F36: 0
A37: LKT01LLR0076 | B37: A.1.4.2 | C37: Keuntungan (kerugian) investasi | E37: =E38+E41 -> 9769008043 | F37: =F38+F41 -> -1868759218
A38: LKT01LLR0077 | B38: A.1.4.2.1 | C38: keuntungan (kerugian) dari transaksi perdagangan Efek | E38: =E39+E40 -> 4560460527 | F38: =F39+F40 -> 569814099
A39: LKT01LLR0078 | B39: A.1.4.2.1.1 | C39: Pihak Berelasi | E39: 4560460527 | F39: 569814099
A40: LKT01LLR0079 | B40: A.1.4.2.1.2 | C40: Pihak ketiga | E40: 0 | F40: 0
A41: LKT01LLR0080 | B41: A.1.4.2.2 | C41: keuntungan (kerugian) yang belum terealisasi atas Efek yang diukur pada Nilai Wajar melalui laba rugi. | E41: =E42+E43 -> 5208547516 | F41: =F42+F43 -> -2438573317
A42: LKT01LLR0081 | B42: A.1.4.2.2.1 | C42: Pihak Berelasi | E42: 5208547516 | F42: -2438573317
A43: LKT01LLR0082 | B43: A.1.4.2.2.2 | C43: Pihak ketiga | E43: 0 | F43: 0
A44: LKT01LLR0022 | B44: A | C44: Total Pendapatan | E44: =E16 -> 308970678934 | F44: =F16 -> 308233286872
A45: LKT01LLR0023 | B45: B | C45: BEBAN | E45: =SUM(E46:E60) -> 273832256209 | F45: =SUM(F46:F60) -> 282514509955
A46: LKT01LLR0024 | B46: B.1 | C46: Beban Kepegawaian | D46: Beban Kepegawaian | E46: 92033099613 | F46: 99173961841
A47: LKT01LLR0025 | B47: B.2 | C47: Komisi agen penjual | D47: Komisi agen penjual | E47: 116215550581 | F47: 115735136182
...

Sheet Laporan Arus Kas
B2: LAKTLEA
B3: 1
C7: =UPPER('Data Umum'!D7) -> PT MANDIRI MANAJEMEN INVESTASI
C9: Laporan Arus Kas
C10: -
C11: ="Untuk Tahun yang Berakhir Pada 31 Desember "&CONCATENATE(TEXT('Data Umum'!D9, "YYYY")) -> Untuk Tahun yang Berakhir Pada 31 Desember 2025
C14: Akun | E14: ="Jumlah (Dalam Rupiah)" -> Jumlah (Dalam Rupiah)
A15: KOMPONEN | B15: MAP CODE | E15: =CONCATENATE(TEXT('Data Umum'!D9, "YYYY")) -> 2025 | F15: =CONCATENATE(TEXT(DATE(YEAR('Data Umum'!D9), MONTH('Data Umum'!D9)-12, DAY('Data Umum'!D9)), "YYYY")) -> 2024
A16: LKT01LAK0001 | B16: A | C16: ARUS KAS DARI AKTIVITAS OPERASI | E16: =SUM(E17:E28) -> 217379395756 | F16: =SUM(F17:F28) -> -130627158648
A17: LKT01LAK0002 | B17: A.1 | C17: Penerimaan Komisi | E17: 0 | F17: 0
A18: LKT01LAK0003 | B18: A.2 | C18: Penerimaan Jasa Manajer Investasi, Penasehat Investasi, Penjamin Emisi, atau Jasa lainnya | E18: 278090164888 | F18: 296605060807
A19: LKT01LAK0004 | B19: A.3 | C19: Penerimaan Penghasilan Bunga | E19: 11399220894 | F19: 15436323884
A20: LKT01LAK0005 | B20: A.4 | C20: Penerimaan atas Efek Diperdagangkan | E20: 0 | F20: 0
A21: LKT01LAK0006 | B21: A.5 | C21: Penerimaan dari Nasabah - bersih | E21: 0 | F21: 0
A22: LKT01LAK0007 | B22: A.6 | C22: Penerimaan dari Lembaga Kliring dan Penjaminan-bersih | E22: 0 | F22: 0
A23: LKT01LAK0008 | B23: A.7 | C23: Pembayaran kepada PE - bersih | E23: 0 | F23: 0
A24: LKT01LAK0009 | B24: A.8 | C24: Penerimaan dari (Pembayaran kepada) Nasabah Marjin - bersih | E24: 0 | F24: 0
A25: LKT01LAK0010 | B25: A.9 | C25: Penjualan Portofolio Efek – bersih | E25: 179521506917 | F25: -171646177522
A26: LKT01LAK0011 | B26: A.10 | C26: Pembayaran kepada Pemasok dan Karyawan | E26: -254267786935 | F26: -267727847130
A27: LKT01LAK0012 | B27: A.11 | C27: Pembayaran Pajak Penghasilan | E27: -9300890414 | F27: -433361087
A28: LKT01LAK0013 | B28: A.12 | C28: Penerimaan (Pembayaran) Lainnya - bersih | E28: 11937180406 | F28: -2861157600
A29: LKT01LAK0014 | B29: A | C29: Arus Kas Neto dari (untuk) Aktivitas Operasi | E29: =E16 -> 217379395756 | F29: =F16 -> -130627158648
A30: LKT01LAK0015 | B30: B | C30: ARUS KAS DARI AKTIVITAS INVESTASI | E30: =SUM(E31:E36) -> -5803085104 | F30: =SUM(F31:F36) -> -2078869805
A31: LKT01LAK0016 | B31: B.1 | C31: Penerimaan Bunga | E31: 0 | F31: 0
A32: LKT01LAK0017 | B32: B.2 | C32: Pencairan Deposito Berjangka | E32: 0 | F32: 0
A33: LKT01LAK0018 | B33: B.3 | C33: Hasil Penjualan Aset Tetap | E33: 17398244 | F33: 0
A34: LKT01LAK0019 | B34: B.4 | C34: Penempatan Deposito Berjangka | E34: 0 | F34: 0
A35: LKT01LAK0020 | B35: B.5 | C35: Perolehan Aset Tetap | E35: -5214767132 | F35: -1477398918
A36: LKT01LAK0021 | B36: B.6 | C36: Penerimaan (Pembayaran) Lainnya - bersih | E36: -605716216 | F36: -601470887
A37: LKT01LAK0022 | B37: B | C37: Arus Kas Neto dari (untuk) Aktivitas Investasi | E37: =E30 -> -5803085104 | F37: =F30 -> -2078869805
A38: LKT01LAK0023 | B38: C | C38: ARUS KAS DARI AKTIVITAS PENDANAAN | E38: =SUM(E39:E45) -> -95804826491 | F38: =SUM(F39:F45) -> -3729264671
A39: LKT01LAK0024 | B39: C.1 | C39: Penerbitan Modal Saham | E39: 0 | F39: 0
A40: LKT01LAK0025 | B40: C.2 | C40: Penerbitan Surat Utang Jangka Pendek | E40: 0 | F40: 0
A41: LKT01LAK0026 | B41: C.3 | C41: Pelunasan Surat Utang Jangka Pendek | E41: 0 | F41: 0
A42: LKT01LAK0027 | B42: C.4 | C42: Penerimaan Pinjaman Bank | E42: 0 | F42: 0
A43: LKT01LAK0028 | B43: C.5 | C43: Pembayaran Pinjaman Bank | E43: 0 | F43: 0
A44: LKT01LAK0029 | B44: C.6 | C44: Pembayaran Bunga | E44: 0 | F44: 0
A45: LKT01LAK0030 | B45: C.7 | C45: Penerimaan (Pembayaran) Lainnya - bersih | E45: -95804826491 | F45: -3729264671
A46: LKT01LAK0031 | B46: C | C46: Arus Kas Neto dari (untuk) Aktivitas Pendanaan | E46: =E38 -> -95804826491 | F46: =F38 -> -3729264671
A47: LKT01LAK0032 | B47: D | C47: Kenaikan (Penurunan) Neto Kas dan Setara Kas | E47: =E16+E30+E38 -> 115771484161 | F47: =F16+F30+F38 -> -136435293124
...

Sheet Laporan Perubahan Ekuitas
B2: LPETLEA
B3: 1
C7: =UPPER('Data Umum'!D7) -> PT MANDIRI MANAJEMEN INVESTASI
C9: Laporan Perubahan Ekuitas
C10: -
C11: ="Untuk Tahun yang Berakhir Pada 31 Desember "&CONCATENATE(TEXT('Data Umum'!D9, "YYYY")) -> Untuk Tahun yang Berakhir Pada 31 Desember 2025
C14: Akun | E14: ="" | F14: ="Saldo Laba*)" -> Saldo Laba*) | H14: ="" | K14: ="Penghasilan Komprehensif Lain" -> Penghasilan Komprehensif Lain | N14: =""
B15: MAP CODE | E15: ="Modal Saham" -> Modal Saham | F15: ="Yang Telah Ditentukan Penggunaannya" -> Yang Telah Ditentukan Penggunaannya | G15: ="Yang Belum Ditentukan Penggunaannya" -> Yang Belum Ditentukan Penggunaannya | H15: ="Tambahan Modal Disetor" -> Tambahan Modal Disetor | I15: ="Selisih Transaksi Pihak Nonpengendali" -> Selisih Transaksi Pihak Nonpengendali | J15: ="Saham Treasuri" -> Saham Treasuri | K15: ="Yang tidak akan direklasifikasi lebih lanjut ke laba rugi" -> Yang tidak akan direklasifikasi lebih lanjut ke laba rugi | L15: ="Yang akan direklasifikasi lebih lanjut ke laba rugi" -> Yang akan direklasifikasi lebih lanjut ke laba rugi | M15: ="Total" -> Total | N15: ="Total" -> Total | O15: ="Kepentingan Nonpengendali" -> Kepentingan Nonpengendali | P15: ="Total Ekuitas" -> Total Ekuitas
B16: LKT01LPE0001 | C16: Saldo per 1 Januari {PREVYYYY} | E16: 60000000000 | F16: 12000000000 | G16: 296348587861 | H16: 0 | I16: 0 | J16: 0 | K16: 0 | L16: 0 | M16: =K16+L16 -> 0 | N16: =E16+F16+G16+H16+I16+J16+M16 -> 368348587861 | O16: -10147059
B17: LKT01LPE0002 | C17: Perubahan Kebijakan Akuntansi | E17: 0 | F17: 0 | G17: 0 | H17: 0 | I17: 0 | J17: 0 | K17: 0 | L17: 0 | M17: =K17+L17 -> 0 | N17: =E17+F17+G17+H17+I17+J17+M17 -> 0 | O17: 0
B18: LKT01LPE0003 | C18: Saldo yang disajikan Kembali | E18: =SUM(E16:E17) -> 60000000000 | F18: =SUM(F16:F17) -> 12000000000 | G18: =SUM(G16:G17) -> 296348587861 | H18: =SUM(H16:H17) -> 0 | I18: =SUM(I16:I17) -> 0 | J18: =SUM(J16:J17) -> 0 | K18: =SUM(K16:K17) -> 0 | L18: =SUM(L16:L17) -> 0 | ... O18: =SUM(O16:O17) -> -10147059 | P18: =N18+O18 -> 368338440802
B19: LKT01LPK0022 | C19: Perubahan Ekuitas pada Tahun (PREVYYYY) | E19: ="" | F19: ="" | G19: ="" | H19: ="" | I19: ="" | J19: ="" | K19: ="" | L19: ="" | ... P19: =""
B20: LKT01LPE0004 | C20: Laba (Rugi) Bersih Periode Berjalan | E20: 0 | F20: 0 | G20: 15417748399 | H20: 0 | I20: 0 | J20: 0 | K20: 0 | L20: 0 | M20: =K20+L20 -> 0 | N20: =E20+F20+G20+H20+I20+J20+M20 -> 15417748399 | O20: 10798066
B21: LKT01LPE0009 | C21: Dividen | E21: 0 | F21: 0 | G21: =-(0.9993*0)-0 -> 0 | H21: 0 | I21: 0 | J21: 0 | K21: 0 | L21: 0 | M21: =K21+L21 -> 0 | N21: =E21+F21+G21+H21+I21+J21+M21 -> 0 | O21: 0
B22: LKT01LPE0006 | C22: Penghasilan Komprehensif Lain | E22: 0 | F22: 0 | G22: -162855381 | H22: 0 | I22: 0 | J22: 0 | K22: 0 | L22: 0 | M22: =K22+L22 -> 0 | N22: =E22+F22+G22+H22+I22+J22+M22 -> -162855381 | O22: =-114079-589 -> -114668
B23: LKT01LPE0011 | C23: Saldo per 31 Desember {PREVYYYY} | E23: =E18+E20+E21+E22 -> 60000000000 | F23: =F18+F20+F21+F22 -> 12000000000 | G23: =G18+G20+G21+G22 -> 311603480879 | H23: =H18+H20+H21+H22 -> 0 | I23: =I18+I20+I21+I22 -> 0 | J23: =J18+J20+J21+J22 -> 0 | K23: =K18+K20+K21+K22 -> 0 | L23: =L18+L20+L21+L22 -> 0 | ... O23: =O18+O20+O21+O22 -> 536339 | P23: =N23+O23 -> 383604017218
B24: LKT01LPK0023 | C24: Perubahan Ekuitas pada Tahun (YYYY) | E24: ="" | F24: ="" | G24: ="" | H24: ="" | I24: ="" | J24: ="" | K24: ="" | L24: ="" | ... P24: =""
B25: LKT01LPE0014 | C25: Laba (Rugi) Bersih Periode Berjalan | E25: 0 | F25: 0 | G25: =0.9993*27272607370 -> 2.7253517e+10 | H25: 0 | I25: 0 | J25: 0 | K25: 0 | L25: 0 | M25: =K25+L25 -> 0 | N25: =E25+F25+G25+H25+I25+J25+M25 -> 2.7253517e+10 | O25: =0.0007*27272607370 -> 19090825
B26: LKT01LPE0019 | C26: Dividen | E26: 0 | F26: 0 | G26: -90000000000 | H26: 0 | I26: 0 | J26: 0 | K26: 0 | L26: 0 | M26: =K26+L26 -> 0 | N26: =E26+F26+G26+H26+I26+J26+M26 -> -90000000000 | O26: =-(0.0007*0)+0 -> 0
B27: LKT01LPE0016 | C27: Penghasilan Komprehensif Lain | E27: 0 | F27: 0 | G27: =0.9993*-755994000 -> -7.554648e+08 | H27: 0 | I27: 0 | J27: 0 | K27: 0 | L27: 0 | M27: =K27+L27 -> 0 | N27: =E27+F27+G27+H27+I27+J27+M27 -> -7.554648e+08 | O27: =-530245+567 -> -529678
B28: LKT01LPK0021 | C28: Saldo per 31 Desember {YYYY} | E28: =E23+E25+E26+E27 -> 60000000000 | F28: =F23+F25+F26+F27 -> 12000000000 | G28: =G23+G25+G26+G27 -> 2.4810153e+11 | H28: =H23+H25+H26+H27 -> 0 | I28: =I23+I25+I26+I27 -> 0 | J28: =J23+J25+J26+J27 -> 0 | K28: =K23+K25+K26+K27 -> 0 | L28: =L23+L25+L26+L27 -> 0 | ... O28: =O23+O25+O26+O27 -> 19097486 | P28: =N28+O28 -> 3.2012063e+11
